대부분의 경우 러스트에서는 코드가 컴파일되기 전에 에러의 가능성을 인지하고 조치를 취해야 한다.

러스트는 에러를 **복구 가능한(recoverable)** 에러와 **복구 불가능한(unrecoverable)** 에러 두 가지 범주로 묶는다. '파일을 찾을 수 없음' 에러 같은 복구 가능한 에러에 대해서는 대부분의 경우 그저 사용자에게 문제를 보고하고 명령을 재시도하도록 하길 원한다. 복구 불가능한 에러는 배열 끝을 넘어선 위치에 접근하는 경우처럼 버그 증상이 나타나를 에러이며, 프로그램을 즉시 멈추기를 원한다.

러스트에는 예외 처리가 없다. 다만 복구 가능한 에러를 위한 `Result<T, E>` 타입과 복구 불가능한 에러가 발생했을 때 프로그램을 종료하는 `panic!` 매크로가 있다.

## panic!으로 복구 불가능한 에러 처리하기

러스트에는 `panic!` 매크로가 있고 이를 일으키는 두 가지 방법이 있다.

- 코드가 패닉을 일으킬 동작을 하는 것
- `panic!`을 명시적으로 호출하는 것

이러한 패닉은 실패 메시지를 출력하고, 되감고(unwind), 스택을 청소하고, 종료한다.

> [!tip] panic!에 대응하여 스택을 되검거나 그만두기
> **되감기(unwinding)** 은 패닉을 발생 시킨 각 함수로부터 스택을 거꾸로 훑어가면서 데이터를 청소한다는 뜻이다. 하지만 간단한 작업이 아니다. 프로젝트 내에서 결과 바이너리를 가능한 한 작게 만들고 싶다면, `Cargo.toml` 내에서 `[profile]` 섹션에 `panic = 'abort'`를 추가하여 되감기를 그만두기로 바꿀 수 있다. 릴리스 모드에서는 패닉 시 그만두기 방식을 쓰고 싶다면, 다음을 추가해라.
> ```toml
> [profile.realease]
> panic = 'abort'

프로그램에서 `panic!`을 호출해 보자.

```rust
fn main() {
	panic!("crash and burn");
}
```

### panic! 백트레이스 이용하기

메모리가 해당 데이터구조의 소유가 아닐지라도, 데이터 구조의 해당 요소에 상응하는 메모리 위치에 있는 모든값을 가져올 수 있는 것을 **버퍼 오버리드(buffer overread)** 라 한다. 접근이 허용되어서는 안 되는 데이터를 읽기 위해 어떤 공격자가 배열 뒤에 저장된 데이터를 읽어낼 요량으로 인덱스를 다루게 되면, 이는 보안 취약점으로 이어질 수 있다.

**백트레이스(backtrace)** 란 어떤 지점에 도달하기까지 호출한 모든 함수의 목록을 말한다. 백트레이스를 읽는 요령은 위에서부터 시작해 작성한 파일이 보일 때까지 읽는 것이다.

`cargo build` 나 `cargo run` 을 `--release` 플래그 없이 실행하면 기본적으로 활성화 된다.

## Result로 복구 가능한 에러 처리하기

[[2. 추리 게임]]의 'Result 타입으로 잠재적 실패 다루기'에서 `Result` 열거형은 다음과 같이 `Ok`와 `Err` 두 개의 배리언트를 갖도로 정의되어 있음을 상기해보자.

```rust
enum Result<T, E> {
	Ok(T),
	Err(E),
}
```

`Result` 값을 반환하는 함수를 호출해보자.

```rust
use std::fs::File;

fn main() {
	let greeting_file_result = File::open("hello.txt");
}
```

이제 반환값에 다른 코드를 처리해보자.

```rust
use std::fs::File;

fn main() {
	let greeting_file_result = File::open("hello.txt");

	let greeting_file = match greeting_file_result {
		Ok(file) => file,
		Err(error) => panic!("Problem opening the file: {:?}", error),
	};
}
```

### 서로 다른 에러에 대해 매칭하기

파일이 없어서 실패했다면 새로운 파일을 만들어서 핸들을 반환하겠다. 그 밖의 이유로 실패했다면 패닉을 일으켜 보자.

```rust
use std::fs::File;

fn main() {
	let greeting_file_result = File::open("hello.txt");

	let greeting_file = match greeting_file_result {
		Ok(file) => file,
		Err(error) => match error.kind() {
			ErrorKink::NotFound => match File::create("hello.txt") {
				Ok(fc) => fc,
				Err(e) => panic!("Problem creating the file: {:?}", e),
			},
			other_error => {
				panic!("Problem opening the file: {:?}", other_error);
			}
		},
	};
}
```

#### Result<T,E>와 match사용에 대한 대안

```rust
use std::fs::File;
use std::io::ErrorKind;

fn main() {
	let greeting_file = File::open("hello.txt").unwrap_or_else(|error| {
		if error.kind() == ErrorKind::NotFound {
			File::create("hello.txt").unwrap_or_else(|error| {
				panic!("Problem creating the file: {:?}", error);
			})
		} else {
			panic!("Problem opening the file: {:?}", error);
		}
	});
}
```

#### 에러 발생 시 패닉을 위한 숏컷: upwrap과 expect
`match`의 사용은 충분히 잘 작동하지만, 장황하고 의도를 항상 잘 전달하는 것도 아니다. `unwrap`은 `Result`의 값이 `Ok`라면 값을 반환하고 `Err`이라면 `panic!` 매크로를 호출해 준다.

```rust
use std::fs::File;

fn main() {
	let greting_file = File::open("hello.txt").upwrap();
}
```

이와 비슷한 `expect` 는 `panic!` 에러 메시지도 선택할 수 있도록 해준다. `upwrap` 대신 `expect`를 이용해 좋은 에러 메시지를 제공하면 의도를 전달하기 좋다.

```rust
use std::fs::File;

fn main() {
	let greeting_file = File::open("hello.txt")
		.expect("hello.txt should be included in this project");
}
```

### 에러 전파하기

함수의 구현체에서 실패할 수 있는 무언가를 호출할 때, 이 함수에서 에러를 처리하는 대신 이함수를 호출하는 코드 쪽으로 에러를 반환해 **에러 전파(error propagation)** 할 수 있다. 호출하는 코드 쪽에 더 많은 제어권을 주는 것이다.

```rust
use std::fs::File;
use std::io::{self, Read};

fn read_username_from_file() -> Result<String, io::Error> {
	let username_file_result = File::open("hello.txt");

	let mut username_file = match username_file_result {
		Ok(file) -> file,
		Err(e) => return Err(e),
	};

	let mut username = String::new();

	match username_file.read_to_string(&mut username) {
		Ok(_) => Ok(username),
		Err(e) => Err(e),
	}
}
```

이 함수가 성공하면 호출한 코드는 `String`을 담은 `Ok` 값을 받을 것이다. 문제가 발생한다면 `Err`값을 받을 것이다.

이 값을 가지고 어떤 일을 할지에 대한 결정은 호출하는 코드 쪽에 달려 있다.

이를 쉽게 해주는 물음표 연산자 `?`에 대해 알아보자.

#### 에러를 전파하기 위한 솟컷: ? 연산자

```rust
use std::fs::File;
use std::io::{self, Read};

fn read_username_from_file() -> Result<String, io::Error> {
	let mut username_file = File::open("hello.txt")?;
	let mut username = String::new();
	username_file.read_to_string(&mut username)?;
	Ok(username)
}
```

`match` 표현식과 거의 같은 방식으로 작동하게끔 정의되어 있다. `Result`의 값이 `Ok`라면 `Ok`안의 값이 얻어지고 프로그램이 계속된다. `Err`이라면 `Err`의 값이 반환된다.

`match`와 `?`의 차이점은 `?` 연산자를 사용할 때의 에러값은 `from` 함수를 거친다는 점이다. `from` 함수는 표준 라이버리 내의 `From` 트레이트에 정의되어 있고 어떤 값의 타입을 다른 타입으로 변환하는 데에 사용한다.

`?` 연산자가 `from` 함수를 호출하면 `?` 연산자가 얻게 되는 에러를 `?` 연산자가 사용된 현재 함수의 반환 타입에 정의된 에러 타입으로 변환한다.

`?` 연산자 뒤에 메서드 호출을 연결할 수 있다.

```rust
use std::fs::File;
use std::io::{self, Read};

fn read_username_from_file() -> Result<String, io::Error> {
	let mut username = String::new();
	
	File::open("hello.txt")?.read_to_string(&mut username)?;
	
	Ok(username)
}
```

`fs::read_to_string`으로 더 짧게 만들 수 있다.

```rust
use std::fs;
use std:: io;

fn read_username_from_file() -> Result<String, io::Error> {
	fs::read_to_string("hello.txt")
}
```

#### ? 연산자가 사용될 수 있는 곳
`?`는 `?`이 사용된 값과 호환 가능한 반환 타입을 가진 함수에서만 사용할 수 있다. 함수의 반환 타입이 `Result`여야 한다.

`Option<T>`에서도 사용 가능하다. 동작은 `Result<T, E>`에서 호출되었을 때의 동작과 비슷하다. `None` 값인 경우 그 함수의 해당 지점으로부터 `None` 값을 일찍 반환할 것이다. `Some`이라면 `Some` 안에 있는 값이 결과 값이 된다.

```rust
fn last_char_of_first_line(text: &str) -> Option<char> {
	text.lines().next()?.chars().last()
}
```

> [!info]
> - `chars`: 문자열 슬라이스의 문자에 대한 반복자를 반환한다.
> - `lines`: 문자열의 라인에 대한 반복자를 반환한다.
> - `last`: 반복자의 마지막 값을 반환한다.

각 메서드가 `None` 값을 반환할 경우 함수의 실행을 멈추고 `None` 값을 반환하게 된다.

중요한건 혼용해서 사용할 수 없다는 점이다. `Result`를 `Option`으로 혹은 그 반대로 자동으로 변환할 수 없다. `Result`의 `ok` 메서드나 `Options`의 `ok_or` 메서드를 사용해 명시적으로 반환해야 한다.

`main`에서 `Result<(), E>`를 반환하도록 해 `?`사용을 가능하게 하려면 다음과 같이 할 수 있다.

```rust
use std::error:Error;
use std::fs:File;

fn main() -> Result<(), Box<dyn Error>> {
	let greeting_file = File::open("hello.txt")?;

	Ok(())
}
```

`Box<dyn Error>` 은 **트레이트 객체** 인데 [[17. 러스트의 객체 지향 프로그래밍 기능]] 에서 배울 예정이다. 지금은 어떤 에러를 의미한다고 알면 된다. 이제 `?`의 연산자 사용이 가능해졌다.

`main` 함수가 `Result<(), E>`를 반환하게 되면 ,실행 파일은 `main`이 `OK(())`를 반환할 경우 0값으로 종료되고 아닐경우 0이 아닌 값으로 종료된다.

`main` 함수가 `std::process:Termination` 트레이트를 구현한 타입을 반환할 수 있다.

## panic!이냐, panic!이 아니냐를 정하는 방법

에러상황에 `panic!` 을 호출할 수 있지만, 그렇게 되면 현 상황은 복구 불가능한 것이라고 결정을 내리는 꼴이 된다. 기본적으로 `Result`를 반환하는 것이 좋다.

예제, 프로토타입, 테스트 같은 상황에서는 `Result`를 반환하는 대신 패닉을 일으키는 코드가 적합하다.

### 예제, 프로토타입 코드, 그리고 테스트

어떤 개념을 묘사하기 위한 예제를 작성 중이라면, 견고한 에러 처리 코드를 포함시키는 것이 오히려 예제의 명확성을 떨어뜨릴 수 있다. `unwrap`, `expect` 같은 메서드의 호출이 애플리케이션의 에러 처리가 필요한 곳을 뜻하는 방식으로 해설될 수 있다.

비슷한 상황으로 에러를 어떻게 처리할지 결정할 준비가 되기 전이라면 ,`unwrap`과 `expect` 메서드가 프로토타이핑할 때 매우 편리합니다. 명확한 표시를 남겨둔다.

만일 테스트 내에서 메서드 호출이 실패한다면, 해당 메서드가 테스트 중인 기능이 아니더라도 전체 테스트를 실패시키도록 한다.

### 컴파일러보다 더 많은 정보를 가지고 있을 때

`Result` 가 `Ok` 값을 가지고 있을 거라 확신할 만한 논리적 근거가 있지만, 컴파일러가 그 논리를 이해할 수 없는 경우라면, `unwrap` 혹은 `expect`를 호출하는 것이 적절할 수 있다. 손수 코드를 조사해 `Err` 배리언트가 나올 리 없음을 확신할 수 있다면 `unwrap`을 호출해도 아무런 문제가 없다. 이런 경우 `Err` 배리언트가 존재하면 안되는 이유를 `expect`에 적어주면 좋다.

### 에러 처리를 위한 가이드라인

나쁜 상태에 처하게 될 가능성이 있을 때는 코드에 `panic!`을 넣는 것이 바람직하다. **나쁜 상태**란 어떤 가정, 보장, 계약, 혹은 불변성이 깨질 때를 뜻하는 것으로, 유효하지 않은 값이나 모순되는 값, 혹은 찾을 수 없는 값이 코드에 전달되는 경우를 말한다.

- 나쁜 상태란 예기치 못한 무언가이며, 이는 사용자가 입력한 데이터가 잘못된 형식인 경우와 같이 흔히 발생할 수 있는 것과는 반대되는 것이다.
- 그 시점 이후의 코드는 매번 해당 문제에 대한 검사를 하는 것이 아니라, 이 나쁜 상태에 있지 않아야만 할 필요가 있다.
- 사용하고 있는 타입 내에 이 정보를 집어넣을 만한 방법이 없다.

만일 어떤 사람이 코드를 호출하고 타당하지 않은 값을 집어넣었다면, 가능한 에러를 반환해 라이브러리의 사용자들이 이러한 경우에 대해 어떤 동작을 원하는지 결정할 수 있도록 하는 것이 가장 좋다.

그러나 계속해서 실행할 경우 보안상의 문제를 일으킬 수 있다면 `panic!`을 사용해 버그를 알려줘 개발중에 이를 고치게 하는것이 최선일 수 있다.

실패가 충분히 예상되는 경우라면 `Result`를 반환하는 것이 여전히 더 적절하다.

함수의 입력이 특정 요구 사항을 만족시킬 경우에만 함수의 행동이 보장되는 **계약**이 있다. 이 계약을 위반했을 때는 패닉을 발생시키는 것이 이치에 맞다. 계약 위반이 항상 호출하는 쪽의 버그임을 나타내고, 호출하는 쪽에서 명시적으로 처리해야 하는 종류의 버그가 아니기 때문이다. 함수에 대한 계약은, 특히 계약 위반이 패닉의 원인이 될 때는 그 함수에 대한 API 문서에 설명되어야 한다.

### 유효성을 위한 커스텀 타입 생성하기

```rust
pub struct Guess {
	value: i32,
}

impl Guess {
	pub fn new(value: i32) -> Guess {
		if value < 1 || value > 100 {
			panic!("Guess value must be between 1 and 100, got {}.", value);
		}
		Guess { value }
	}
	pub fn value(&self) -> i32 {
		self.value
	}
}
```

여기서 `panic`을 일으키는 이유는 `Guess`를 생성하는 것에 대해서 `new` 가 요구하는 계약을 위반하기 때문이다. 패닉을 일으킬 수 있는 조건은 공개 API 문서에서 다뤄져야 한다. 이에 대해서는 [[14. 카고와 crates.io 더 알아보기]] 에서 배운다.

여기서 `value` 필드는 비공개 이기 때문에 `value` **게터(getter)** 메서드를 정의해 줬다. 이 `Guess` 구조체를 사용하는 코드는 `value`를 직접 설정할 수 없기 때문에 `new`를 통해서만 호출되어 생성될 수 있다. 이는 **중요하다.**